Workbook

Sheet Pricing strategy 
A1: SKU Type | B1: Benchmark | C1: acceptable range | D1: threshhold | E1: Margin Rule | F1: Maximum price increase (example sku 1 KVI sku 1 non-KVI | G1: Max price decrease (example sku 1 KVI sku 1 non-KVI | H1: Remark | I1: Promo rule | J1: Rounding rule(kuwait)
A2: KVI items | B2: Lowest price in the market | C2: 2-4% lower than the lowest in market | D2: X | E2: if margin drops less than 12% or increases more than 16%, a price change is recommended | F2: 2 | G2: 2.2 | H2: this is similar to MARS, automated price changing implemented in Amazon to match buy box, this should be directly related to competition benchmark , profitability, & price positioning | I2: Flag & recommend future change | J2: pricing is as follows 0.100, 0.250, 0.50, 0.990 ( pyhcological pricing)
A3: Non-KVI | B3: vs market average price | C3: 0-2% lower than average market price | D3: never price 5% above market ( will look expensive vs carrefour) | E3: if margin drops less than 16 % or increases more than 20% a price change is recommended | F3: 2.4 | G3: 2.65 | H3: this is similar to MARS, automated price changing implemented in Amazon to match buy box, this should be directly related to competition benchmark , profitability, & price positioning | I3: Flag & recommend future change | J3: pricing is as follows 0.100, 0.250, 0.50, 0.990 ( pyhcological pricing)
A4: Premium / slow movers | B4: Above Spinnys signature ( premium store) | C4: 1-5% above spinnys signature | D4: X | E4: if margin increases less than 20%, recommend price change | F4: x | G4: x | H4: this is similar to MARS, automated price changing implemented in Amazon to match buy box, this should be directly related to competition benchmark , profitability, & price positioning | I4: Ignore, promotions on premium items are rare | J4: pricing is as follows 0.100, 0.250, 0.50, 0.990 ( pyhcological pricing)

Sheet Pricing Engine V1
A1: SKU | B1: Product_Name | C1: Category | D1: subcategory | E1: Brand | F1: Pack_Size | G1: Tawfeer_Price | H1: Cost | I1: Margin_Floor | J1: Current GM% | K1: Gap vs benchmark | L1: Margin Flag | M1: Price Positioning | N1: recommended pricing action | O1: Recommended price | P1: Price change % | Q1: Difference vs Lowest in the market/ Average market price | R1: New GM% after price recommendation | S1: Rule conflict | T1: Action | U1: Decision priority | V1: KVI_Flag | W1: Promo_Flag | X1: Carrefour_Price | Y1: Spinneys_Price | Z1: MetroMart_Price | AA1: Lowest market price | AB1: average market price | AC1: Units_Sold_Last_Week | AD1: Inventory_Level | AE1: Stock cover | AF1: Inventory interpretation | AG1: recommended inventory action | AH1: Store_Count | AI1: Last_Price_Change_Date | AJ1: Segment | AK1: Target GM% | AL1: Target Stock Weeks | AM1: Margin Safe Min Price | AN1: Lowest_Market_Price | AO1: Avg_Market_Price
A2: 1001 | B2: Milk 1L | C2: Dairy | D2: milk | E2: Generic | F2: 1L | G2: 2.5 | H2: =ROUND(G2*(1-AK2),2) -> 2.15 | I2: =IF(V2="Yes",0.12,0.16) -> 0.12 | J2: =(G2-H2)/G2 -> 0.14 | K2: =IF(V2="Yes",(G2-AA2)/AA2,(G2-AB2)/AB2) -> 0.063829787 | L2: =IF(V2="Yes", IF(J2<0.12,"Below margin threshold",IF(J2>0.16,"Above margin threshold","Within margin threshold")), IF(J2<0.16,"Below margin threshold",IF(J2>0.2,"Above margin threshold","Within margin threshold"))) -> Within margin threshold | M2: =IF(V2="Yes", IF((G2-AA2)/AA2>-0.02,"Too expensive",IF((G2-AA2)/AA2<-0.04,"Too cheap","Within range")), IF(G2>AB2,"Too expensive",IF(G2<AB2*0.98,"Too cheap","Within range"))) -> Too expensive | N2: =IF(O2<G2,"Decrease Price",IF(O2>G2,"Increase Price","Keep")) -> Decrease Price | O2: =IF(U2="No decision priority",G2, IF(V2="Yes", MROUND( IF(((AA2*0.98)-H2)/(AA2*0.98)<0.12, H2/(1-0.12), IF(((AA2*0.98)-H2)/(AA2*0.98)>0.16, H2/(1-0.16), AA2*0.98)), 0.05), MROUND( IF(((AB2*0.98)-H2)/(AB2*0.98)<0.16, H2/(1-0.16), IF(((AB2*0.98)-H2)/(AB2*0.98)>0.2, H2/(1-0.2), AB2*0.98)), 0.05))) -> 2.45 | P2: =(O2/G2)-1 -> -0.02 | Q2: =IF(V2="Yes",(O2-AA2)/AA2,(O2-AB2)/AB2) -> 0.042553191 | R2: =(O2-H2)/O2 -> 0.12244898 | S2: =IF(V2="Yes", IF(AND(R2>=0.12,R2<=0.16,Q2<=-0.02,Q2>=-0.04),"No conflict", IF(OR(Q2>-0.02,Q2<-0.04),"Price positioning conflict", "Margin conflict")), IF(AND(R2>=0.16,R2<=0.2,O2<=AB2,O2>=AB2*0.98),"No conflict", IF(OR(R2<0.16,R2>0.2),"Margin conflict", "Price positioning conflict"))) -> Price positioning conflict | T2: =IF(S2="No conflict","Approve","Review") -> Review | U2: =IF(AND(L2="Within margin threshold",M2="Within range"),"No decision priority",IF(V2="Yes","Price positioning","Margin")) -> Price positioning | V2: Yes | W2: No | X2: 2.35 | Y2: 2.55 | Z2: 2.4 | AA2: =MIN(X2:Z2) -> 2.35 | AB2: =AVERAGE(X2:Z2) -> 2.4333333 | AC2: 720 | AD2: =ROUND(AC2*AN2,0) -> 1692 | AE2: =AD2/AC2 -> 2.35 | AF2: =IF(AE2<4,"Understocked",IF(AE2<=Model_Controls!$B$27,"Rightly stocked","Overstocked")) -> Understocked | AG2: =IF(AF2="Understocked", "Increase next order stock cover", IF(AF2="Rightly stocked", "Keep next order stock cover", IF(AF2="Overstocked", "Reduce next order stock cover",""))) -> Increase next order stock cover | AH2: 28 | AI2: 46075 | AJ2: =IF(V2="Yes","KVI",IF(AC2<180,"Slow mover","Core")) -> KVI | AK2: =MIN(Model_Controls!$B$29-0.005,MAX(Model_Controls!$B$28+0.005,I2+IF(MOD($A2,9)=0,-Model_Controls!$B$10+MOD($A2,2)*0.005,IF(V2="Yes",Model_Controls!$B$6+MOD($A2,4)*Model_Controls!$B$9,IF(AC2<180,Model_Controls!$B$8+MOD($A2,3)*Model_Controls!$B$9,Model_Controls!$B$7+MOD($A2,5)*Model_Controls!$B$9))))) -> 0.14 | AL2: =IF(MOD($A2,9)=0,Model_Controls!$B$14+MOD($A2,4)*Model_Controls!$B$18,IF(V2="Yes",Model_Controls!$B$11+MOD($A2,4)*Model_Controls!$B$15,IF(AC2<180,Model_Controls!$B$13+MOD($A2,4)*Model_Controls!$B$17,Model_Controls!$B$12+MOD($A2,5)*Model_Controls!$B$16))) -> 5 | AM2: =H2/(1-I2) -> 2.4431818 | AN2: =MIN(X2:Z2) -> 2.35 | AO2: =AVERAGE(X2:Z2) -> 2.4333333
A3: 1002 | B3: Milk 2L | C3: Dairy | D3: milk | E3: Generic | F3: 2L | G3: 4.8 | H3: =ROUND(G3*(1-AK3),2) -> 4.08 | I3: =IF(V3="Yes",0.12,0.16) -> 0.12 | J3: =(G3-H3)/G3 -> 0.15 | K3: =IF(V3="Yes",(G3-AA3)/AA3,(G3-AB3)/AB3) -> 0.043478261 | L3: =IF(V3="Yes", IF(J3<0.12,"Below margin threshold",IF(J3>0.16,"Above margin threshold","Within margin threshold")), IF(J3<0.16,"Below margin threshold",IF(J3>0.2,"Above margin threshold","Within margin threshold"))) -> Within margin threshold | M3: =IF(V3="Yes", IF((G3-AA3)/AA3>-0.02,"Too expensive",IF((G3-AA3)/AA3<-0.04,"Too cheap","Within range")), IF(G3>AB3,"Too expensive",IF(G3<AB3*0.98,"Too cheap","Within range"))) -> Too expensive | N3: =IF(O3<G3,"Decrease Price",IF(O3>G3,"Increase Price","Keep")) -> Decrease Price | O3: =IF(U3="No decision priority",G3, IF(V3="Yes", MROUND( IF(((AA3*0.98)-H3)/(AA3*0.98)<0.12, H3/(1-0.12), IF(((AA3*0.98)-H3)/(AA3*0.98)>0.16, H3/(1-0.16), AA3*0.98)), 0.05), MROUND( IF(((AB3*0.98)-H3)/(AB3*0.98)<0.16, H3/(1-0.16), IF(((AB3*0.98)-H3)/(AB3*0.98)>0.2, H3/(1-0.2), AB3*0.98)), 0.05))) -> 4.65 | P3: =(O3/G3)-1 -> -0.03125 | Q3: =IF(V3="Yes",(O3-AA3)/AA3,(O3-AB3)/AB3) -> 0.010869565 | R3: =(O3-H3)/O3 -> 0.12258065 | S3: =IF(V3="Yes", IF(AND(R3>=0.12,R3<=0.16,Q3<=-0.02,Q3>=-0.04),"No conflict", IF(OR(Q3>-0.02,Q3<-0.04),"Price positioning conflict", "Margin conflict")), IF(AND(R3>=0.16,R3<=0.2,O3<=AB3,O3>=AB3*0.98),"No conflict", IF(OR(R3<0.16,R3>0.2),"Margin conflict", "Price positioning conflict"))) -> Price positioning conflict | T3: =IF(S3="No conflict","Approve","Review") -> Review | U3: =IF(AND(L3="Within margin threshold",M3="Within range"),"No decision priority",IF(V3="Yes","Price positioning","Margin")) -> Price positioning | V3: Yes | W3: No | X3: 4.6 | Y3: 4.95 | Z3: 4.7 | AA3: =MIN(X3:Z3) -> 4.6 | AB3: =AVERAGE(X3:Z3) -> 4.75 | AC3: 610 | AD3: =ROUND(AC3*AN3,0) -> 2806 | AE3: =AD3/AC3 -> 4.6 | AF3: =IF(AE3<4,"Understocked",IF(AE3<=Model_Controls!$B$27,"Rightly stocked","Overstocked")) -> Rightly stocked | AG3: =IF(AF3="Understocked", "Increase next order stock cover", IF(AF3="Rightly stocked", "Keep next order stock cover", IF(AF3="Overstocked", "Reduce next order stock cover",""))) -> Keep next order stock cover | AH3: 28 | AI3: 46075 | AJ3: =IF(V3="Yes","KVI",IF(AC3<180,"Slow mover","Core")) -> KVI | AK3: =MIN(Model_Controls!$B$29-0.005,MAX(Model_Controls!$B$28+0.005,I3+IF(MOD($A3,9)=0,-Model_Controls!$B$10+MOD($A3,2)*0.005,IF(V3="Yes",Model_Controls!$B$6+MOD($A3,4)*Model_Controls!$B$9,IF(AC3<180,Model_Controls!$B$8+MOD($A3,3)*Model_Controls!$B$9,Model_Controls!$B$7+MOD($A3,5)*Model_Controls!$B$9))))) -> 0.15 | AL3: =IF(MOD($A3,9)=0,Model_Controls!$B$14+MOD($A3,4)*Model_Controls!$B$18,IF(V3="Yes",Model_Controls!$B$11+MOD($A3,4)*Model_Controls!$B$15,IF(AC3<180,Model_Controls!$B$13+MOD($A3,4)*Model_Controls!$B$17,Model_Controls!$B$12+MOD($A3,5)*Model_Controls!$B$16))) -> 5.5 | AM3: =H3/(1-I3) -> 4.6363636 | AN3: =MIN(X3:Z3) -> 4.6 | AO3: =AVERAGE(X3:Z3) -> 4.75
A4: 1003 | B4: Skim Milk 1L | C4: Dairy | D4: milk | E4: Generic | F4: 1L | G4: 2.6 | H4: =ROUND(G4*(1-AK4),2) -> 2.09 | I4: =IF(V4="Yes",0.12,0.16) -> 0.16 | J4: =(G4-H4)/G4 -> 0.19615385 | K4: =IF(V4="Yes",(G4-AA4)/AA4,(G4-AB4)/AB4) -> 0.019607843 | L4: =IF(V4="Yes", IF(J4<0.12,"Below margin threshold",IF(J4>0.16,"Above margin threshold","Within margin threshold")), IF(J4<0.16,"Below margin threshold",IF(J4>0.2,"Above margin threshold","Within margin threshold"))) -> Within margin threshold | M4: =IF(V4="Yes", IF((G4-AA4)/AA4>-0.02,"Too expensive",IF((G4-AA4)/AA4<-0.04,"Too cheap","Within range")), IF(G4>AB4,"Too expensive",IF(G4<AB4*0.98,"Too cheap","Within range"))) -> Too expensive | N4: =IF(O4<G4,"Decrease Price",IF(O4>G4,"Increase Price","Keep")) -> Decrease Price | O4: =IF(U4="No decision priority",G4, IF(V4="Yes", MROUND( IF(((AA4*0.98)-H4)/(AA4*0.98)<0.12, H4/(1-0.12), IF(((AA4*0.98)-H4)/(AA4*0.98)>0.16, H4/(1-0.16), AA4*0.98)), 0.05), MROUND( IF(((AB4*0.98)-H4)/(AB4*0.98)<0.16, H4/(1-0.16), IF(((AB4*0.98)-H4)/(AB4*0.98)>0.2, H4/(1-0.2), AB4*0.98)), 0.05))) -> 2.5 | P4: =(O4/G4)-1 -> -0.038461538 | Q4: =IF(V4="Yes",(O4-AA4)/AA4,(O4-AB4)/AB4) -> -0.019607843 | R4: =(O4-H4)/O4 -> 0.164 | S4: =IF(V4="Yes", IF(AND(R4>=0.12,R4<=0.16,Q4<=-0.02,Q4>=-0.04),"No conflict", IF(OR(Q4>-0.02,Q4<-0.04),"Price positioning conflict", "Margin conflict")), IF(AND(R4>=0.16,R4<=0.2,O4<=AB4,O4>=AB4*0.98),"No conflict", IF(OR(R4<0.16,R4>0.2),"Margin conflict", "Price positioning conflict"))) -> No conflict | T4: =IF(S4="No conflict","Approve","Review") -> Approve | U4: =IF(AND(L4="Within margin threshold",M4="Within range"),"No decision priority",IF(V4="Yes","Price positioning","Margin")) -> Margin | V4: No | W4: No | X4: 2.45 | Y4: 2.7 | Z4: 2.5 | AA4: =MIN(X4:Z4) -> 2.45 | AB4: =AVERAGE(X4:Z4) -> 2.55 | AC4: 410 | AD4: =ROUND(AC4*AN4,0) -> 1005 | AE4: =AD4/AC4 -> 2.4512195 | AF4: =IF(AE4<4,"Understocked",IF(AE4<=Model_Controls!$B$27,"Rightly stocked","Overstocked")) -> Understocked | AG4: =IF(AF4="Understocked", "Increase next order stock cover", IF(AF4="Rightly stocked", "Keep next order stock cover", IF(AF4="Overstocked", "Reduce next order stock cover",""))) -> Increase next order stock cover | AH4: 24 | AI4: 46071 | AJ4: =IF(V4="Yes","KVI",IF(AC4<180,"Slow mover","Core")) -> Core | AK4: =MIN(Model_Controls!$B$29-0.005,MAX(Model_Controls!$B$28+0.005,I4+IF(MOD($A4,9)=0,-Model_Controls!$B$10+MOD($A4,2)*0.005,IF(V4="Yes",Model_Controls!$B$6+MOD($A4,4)*Model_Controls!$B$9,IF(AC4<180,Model_Controls!$B$8+MOD($A4,3)*Model_Controls!$B$9,Model_Controls!$B$7+MOD($A4,5)*Model_Controls!$B$9))))) -> 0.195 | AL4: =IF(MOD($A4,9)=0,Model_Controls!$B$14+MOD($A4,4)*Model_Controls!$B$18,IF(V4="Yes",Model_Controls!$B$11+MOD($A4,4)*Model_Controls!$B$15,IF(AC4<180,Model_Controls!$B$13+MOD($A4,4)*Model_Controls!$B$17,Model_Controls!$B$12+MOD($A4,5)*Model_Controls!$B$16))) -> 6.7 | AM4: =H4/(1-I4) -> 2.4880952 | AN4: =MIN(X4:Z4) -> 2.45 | AO4: =AVERAGE(X4:Z4) -> 2.55
A5: 1004 | B5: Chocolate Milk 1L | C5: Dairy | D5: milk | E5: Generic | F5: 1L | G5: 3.2 | H5: =ROUND(G5*(1-AK5),2) -> 2.58 | I5: =IF(V5="Yes",0.12,0.16) -> 0.16 | J5: =(G5-H5)/G5 -> 0.19375 | K5: =IF(V5="Yes",(G5-AA5)/AA5,(G5-AB5)/AB5) -> 1.3877788e-16 | L5: =IF(V5="Yes", IF(J5<0.12,"Below margin threshold",IF(J5>0.16,"Above margin threshold","Within margin threshold")), IF(J5<0.16,"Below margin threshold",IF(J5>0.2,"Above margin threshold","Within margin threshold"))) -> Within margin threshold | M5: =IF(V5="Yes", IF((G5-AA5)/AA5>-0.02,"Too expensive",IF((G5-AA5)/AA5<-0.04,"Too cheap","Within range")), IF(G5>AB5,"Too expensive",IF(G5<AB5*0.98,"Too cheap","Within range"))) -> Within range | N5: =IF(O5<G5,"Decrease Price",IF(O5>G5,"Increase Price","Keep")) -> Keep | O5: =IF(U5="No decision priority",G5, IF(V5="Yes", MROUND( IF(((AA5*0.98)-H5)/(AA5*0.98)<0.12, H5/(1-0.12), IF(((AA5*0.98)-H5)/(AA5*0.98)>0.16, H5/(1-0.16), AA5*0.98)), 0.05), MROUND( IF(((AB5*0.98)-H5)/(AB5*0.98)<0.16, H5/(1-0.16), IF(((AB5*0.98)-H5)/(AB5*0.98)>0.2, H5/(1-0.2), AB5*0.98)), 0.05))) -> 3.2 | P5: =(O5/G5)-1 -> 0 | Q5: =IF(V5="Yes",(O5-AA5)/AA5,(O5-AB5)/AB5) -> 1.3877788e-16 | R5: =(O5-H5)/O5 -> 0.19375 | S5: =IF(V5="Yes", IF(AND(R5>=0.12,R5<=0.16,Q5<=-0.02,Q5>=-0.04),"No conflict", IF(OR(Q5>-0.02,Q5<-0.04),"Price positioning conflict", "Margin conflict")), IF(AND(R5>=0.16,R5<=0.2,O5<=AB5,O5>=AB5*0.98),"No conflict", IF(OR(R5<0.16,R5>0.2),"Margin conflict", "Price positioning conflict"))) -> No conflict | T5: =IF(S5="No conflict","Approve","Review") -> Approve | U5: =IF(AND(L5="Within margin threshold",M5="Within range"),"No decision priority",IF(V5="Yes","Price positioning","Margin")) -> No decision priority | V5: No | W5: No | X5: 3.1 | Y5: 3.35 | Z5: 3.15 | AA5: =MIN(X5:Z5) -> 3.1 | AB5: =AVERAGE(X5:Z5) -> 3.2 | AC5: 280 | AD5: =ROUND(AC5*AN5,0) -> 868 | AE5: =AD5/AC5 -> 3.1 | AF5: =IF(AE5<4,"Understocked",IF(AE5<=Model_Controls!$B$27,"Rightly stocked","Overstocked")) -> Understocked | AG5: =IF(AF5="Understocked", "Increase next order stock cover", IF(AF5="Rightly stocked", "Keep next order stock cover", IF(AF5="Overstocked", "Reduce next order stock cover",""))) -> Increase next order stock cover | AH5: 24 | AI5: 46068 | AJ5: =IF(V5="Yes","KVI",IF(AC5<180,"Slow mover","Core")) -> Core | AK5: =MIN(Model_Controls!$B$29-0.005,MAX(Model_Controls!$B$28+0.005,I5+IF(MOD($A5,9)=0,-Model_Controls!$B$10+MOD($A5,2)*0.005,IF(V5="Yes",Model_Controls!$B$6+MOD($A5,4)*Model_Controls!$B$9,IF(AC5<180,Model_Controls!$B$8+MOD($A5,3)*Model_Controls!$B$9,Model_Controls!$B$7+MOD($A5,5)*Model_Controls!$B$9))))) -> 0.195 | AL5: =IF(MOD($A5,9)=0,Model_Controls!$B$14+MOD($A5,4)*Model_Controls!$B$18,IF(V5="Yes",Model_Controls!$B$11+MOD($A5,4)*Model_Controls!$B$15,IF(AC5<180,Model_Controls!$B$13+MOD($A5,4)*Model_Controls!$B$17,Model_Controls!$B$12+MOD($A5,5)*Model_Controls!$B$16))) -> 7.1 | AM5: =H5/(1-I5) -> 3.0714286 | AN5: =MIN(X5:Z5) -> 3.1 | AO5: =AVERAGE(X5:Z5) -> 3.2
A6: 1005 | B6: Yogurt Plain 500g | C6: Dairy | D6: Yogurt | E6: Generic | F6: 500g | G6: 3.2 | H6: =ROUND(G6*(1-AK6),2) -> 2.75 | I6: =IF(V6="Yes",0.12,0.16) -> 0.12 | J6: =(G6-H6)/G6 -> 0.140625 | K6: =IF(V6="Yes",(G6-AA6)/AA6,(G6-AB6)/AB6) -> 0.049180328 | L6: =IF(V6="Yes", IF(J6<0.12,"Below margin threshold",IF(J6>0.16,"Above margin threshold","Within margin threshold")), IF(J6<0.16,"Below margin threshold",IF(J6>0.2,"Above margin threshold","Within margin threshold"))) -> Within margin threshold | M6: =IF(V6="Yes", IF((G6-AA6)/AA6>-0.02,"Too expensive",IF((G6-AA6)/AA6<-0.04,"Too cheap","Within range")), IF(G6>AB6,"Too expensive",IF(G6<AB6*0.98,"Too cheap","Within range"))) -> Too expensive | N6: =IF(O6<G6,"Decrease Price",IF(O6>G6,"Increase Price","Keep")) -> Decrease Price | O6: =IF(U6="No decision priority",G6, IF(V6="Yes", MROUND( IF(((AA6*0.98)-H6)/(AA6*0.98)<0.12, H6/(1-0.12), IF(((AA6*0.98)-H6)/(AA6*0.98)>0.16, H6/(1-0.16), AA6*0.98)), 0.05), MROUND( IF(((AB6*0.98)-H6)/(AB6*0.98)<0.16, H6/(1-0.16), IF(((AB6*0.98)-H6)/(AB6*0.98)>0.2, H6/(1-0.2), AB6*0.98)), 0.05))) -> 3.15 | P6: =(O6/G6)-1 -> -0.015625 | Q6: =IF(V6="Yes",(O6-AA6)/AA6,(O6-AB6)/AB6) -> 0.032786885 | R6: =(O6-H6)/O6 -> 0.12698413 | S6: =IF(V6="Yes", IF(AND(R6>=0.12,R6<=0.16,Q6<=-0.02,Q6>=-0.04),"No conflict", IF(OR(Q6>-0.02,Q6<-0.04),"Price positioning conflict", "Margin conflict")), IF(AND(R6>=0.16,R6<=0.2,O6<=AB6,O6>=AB6*0.98),"No conflict", IF(OR(R6<0.16,R6>0.2),"Margin conflict", "Price positioning conflict"))) -> Price positioning conflict | T6: =IF(S6="No conflict","Approve","Review") -> Review | U6: =IF(AND(L6="Within margin threshold",M6="Within range"),"No decision priority",IF(V6="Yes","Price positioning","Margin")) -> Price positioning | V6: Yes | W6: No | X6: 3.05 | Y6: 3.35 | Z6: 3.1 | AA6: =MIN(X6:Z6) -> 3.05 | AB6: =AVERAGE(X6:Z6) -> 3.1666667 | AC6: 340 | AD6: =ROUND(AC6*AN6,0) -> 1037 | AE6: =AD6/AC6 -> 3.05 | AF6: =IF(AE6<4,"Understocked",IF(AE6<=Model_Controls!$B$27,"Rightly stocked","Overstocked")) -> Understocked | AG6: =IF(AF6="Understocked", "Increase next order stock cover", IF(AF6="Rightly stocked", "Keep next order stock cover", IF(AF6="Overstocked", "Reduce next order stock cover",""))) -> Increase next order stock cover | AH6: 26 | AI6: 46071 | AJ6: =IF(V6="Yes","KVI",IF(AC6<180,"Slow mover","Core")) -> KVI | AK6: =MIN(Model_Controls!$B$29-0.005,MAX(Model_Controls!$B$28+0.005,I6+IF(MOD($A6,9)=0,-Model_Controls!$B$10+MOD($A6,2)*0.005,IF(V6="Yes",Model_Controls!$B$6+MOD($A6,4)*Model_Controls!$B$9,IF(AC6<180,Model_Controls!$B$8+MOD($A6,3)*Model_Controls!$B$9,Model_Controls!$B$7+MOD($A6,5)*Model_Controls!$B$9))))) -> 0.14 | AL6: =IF(MOD($A6,9)=0,Model_Controls!$B$14+MOD($A6,4)*Model_Controls!$B$18,IF(V6="Yes",Model_Controls!$B$11+MOD($A6,4)*Model_Controls!$B$15,IF(AC6<180,Model_Controls!$B$13+MOD($A6,4)*Model_Controls!$B$17,Model_Controls!$B$12+MOD($A6,5)*Model_Controls!$B$16))) -> 5 | AM6: =H6/(1-I6) -> 3.125 | AN6: =MIN(X6:Z6) -> 3.05 | AO6: =AVERAGE(X6:Z6) -> 3.1666667
A7: 1006 | B7: Yogurt Strawberry 500g | C7: Dairy | D7: Falovored yogurt | E7: Generic | F7: 500g | G7: 3.4 | H7: =ROUND(G7*(1-AK7),2) -> 2.81 | I7: =IF(V7="Yes",0.12,0.16) -> 0.16 | J7: =(G7-H7)/G7 -> 0.17352941 | K7: =IF(V7="Yes",(G7-AA7)/AA7,(G7-AB7)/AB7) -> 0.014925373 | L7: =IF(V7="Yes", IF(J7<0.12,"Below margin threshold",IF(J7>0.16,"Above margin threshold","Within margin threshold")), IF(J7<0.16,"Below margin threshold",IF(J7>0.2,"Above margin threshold","Within margin threshold"))) -> Within margin threshold | M7: =IF(V7="Yes", IF((G7-AA7)/AA7>-0.02,"Too expensive",IF((G7-AA7)/AA7<-0.04,"Too cheap","Within range")), IF(G7>AB7,"Too expensive",IF(G7<AB7*0.98,"Too cheap","Within range"))) -> Too expensive | N7: =IF(O7<G7,"Decrease Price",IF(O7>G7,"Increase Price","Keep")) -> Decrease Price | O7: =IF(U7="No decision priority",G7, IF(V7="Yes", MROUND( IF(((AA7*0.98)-H7)/(AA7*0.98)<0.12, H7/(1-0.12), IF(((AA7*0.98)-H7)/(AA7*0.98)>0.16, H7/(1-0.16), AA7*0.98)), 0.05), MROUND( IF(((AB7*0.98)-H7)/(AB7*0.98)<0.16, H7/(1-0.16), IF(((AB7*0.98)-H7)/(AB7*0.98)>0.2, H7/(1-0.2), AB7*0.98)), 0.05))) -> 3.35 | P7: =(O7/G7)-1 -> -0.014705882 | Q7: =IF(V7="Yes",(O7-AA7)/AA7,(O7-AB7)/AB7) -> 0 | R7: =(O7-H7)/O7 -> 0.16119403 | S7: =IF(V7="Yes", IF(AND(R7>=0.12,R7<=0.16,Q7<=-0.02,Q7>=-0.04),"No conflict", IF(OR(Q7>-0.02,Q7<-0.04),"Price positioning conflict", "Margin conflict")), IF(AND(R7>=0.16,R7<=0.2,O7<=AB7,O7>=AB7*0.98),"No conflict", IF(OR(R7<0.16,R7>0.2),"Margin conflict", "Price positioning conflict"))) -> No conflict | T7: =IF(S7="No conflict","Approve","Review") -> Approve | U7: =IF(AND(L7="Within margin threshold",M7="Within range"),"No decision priority",IF(V7="Yes","Price positioning","Margin")) -> Margin | V7: No | W7: No | X7: 3.2 | Y7: 3.55 | Z7: 3.3 | AA7: =MIN(X7:Z7) -> 3.2 | AB7: =AVERAGE(X7:Z7) -> 3.35 | AC7: 310 | AD7: =ROUND(AC7*AN7,0) -> 992 | AE7: =AD7/AC7 -> 3.2 | AF7: =IF(AE7<4,"Understocked",IF(AE7<=Model_Controls!$B$27,"Rightly stocked","Overstocked")) -> Understocked | AG7: =IF(AF7="Understocked", "Increase next order stock cover", IF(AF7="Rightly stocked", "Keep next order stock cover", IF(AF7="Overstocked", "Reduce next order stock cover",""))) -> Increase next order stock cover | AH7: 26 | AI7: 46070 | AJ7: =IF(V7="Yes","KVI",IF(AC7<180,"Slow mover","Core")) -> Core | AK7: =MIN(Model_Controls!$B$29-0.005,MAX(Model_Controls!$B$28+0.005,I7+IF(MOD($A7,9)=0,-Model_Controls!$B$10+MOD($A7,2)*0.005,IF(V7="Yes",Model_Controls!$B$6+MOD($A7,4)*Model_Controls!$B$9,IF(AC7<180,Model_Controls!$B$8+MOD($A7,3)*Model_Controls!$B$9,Model_Controls!$B$7+MOD($A7,5)*Model_Controls!$B$9))))) -> 0.175 | AL7: =IF(MOD($A7,9)=0,Model_Controls!$B$14+MOD($A7,4)*Model_Controls!$B$18,IF(V7="Yes",Model_Controls!$B$11+MOD($A7,4)*Model_Controls!$B$15,IF(AC7<180,Model_Controls!$B$13+MOD($A7,4)*Model_Controls!$B$17,Model_Controls!$B$12+MOD($A7,5)*Model_Controls!$B$16))) -> 5.9 | AM7: =H7/(1-I7) -> 3.3452381 | AN7: =MIN(X7:Z7) -> 3.2 | AO7: =AVERAGE(X7:Z7) -> 3.35
A8: 1007 | B8: Greek Yogurt 400g | C8: Dairy | D8: Greek yogurt | E8: Generic | F8: 400g | G8: 4.1 | H8: =ROUND(G8*(1-AK8),2) -> 3.34 | I8: =IF(V8="Yes",0.12,0.16) -> 0.16 | J8: =(G8-H8)/G8 -> 0.18536585 | K8: =IF(V8="Yes",(G8-AA8)/AA8,(G8-AB8)/AB8) -> 0.0081967213 | L8: =IF(V8="Yes", IF(J8<0.12,"Below margin threshold",IF(J8>0.16,"Above margin threshold","Within margin threshold")), IF(J8<0.16,"Below margin threshold",IF(J8>0.2,"Above margin threshold","Within margin threshold"))) -> Within margin threshold | M8: =IF(V8="Yes", IF((G8-AA8)/AA8>-0.02,"Too expensive",IF((G8-AA8)/AA8<-0.04,"Too cheap","Within range")), IF(G8>AB8,"Too expensive",IF(G8<AB8*0.98,"Too cheap","Within range"))) -> Too expensive | N8: =IF(O8<G8,"Decrease Price",IF(O8>G8,"Increase Price","Keep")) -> Decrease Price | O8: =IF(U8="No decision priority",G8, IF(V8="Yes", MROUND( IF(((AA8*0.98)-H8)/(AA8*0.98)<0.12, H8/(1-0.12), IF(((AA8*0.98)-H8)/(AA8*0.98)>0.16, H8/(1-0.16), AA8*0.98)), 0.05), MROUND( IF(((AB8*0.98)-H8)/(AB8*0.98)<0.16, H8/(1-0.16), IF(((AB8*0.98)-H8)/(AB8*0.98)>0.2, H8/(1-0.2), AB8*0.98)), 0.05))) -> 4 | P8: =(O8/G8)-1 -> -0.024390244 | Q8: =IF(V8="Yes",(O8-AA8)/AA8,(O8-AB8)/AB8) -> -0.016393443 | R8: =(O8-H8)/O8 -> 0.165 | S8: =IF(V8="Yes", IF(AND(R8>=0.12,R8<=0.16,Q8<=-0.02,Q8>=-0.04),"No conflict", IF(OR(Q8>-0.02,Q8<-0.04),"Price positioning conflict", "Margin conflict")), IF(AND(R8>=0.16,R8<=0.2,O8<=AB8,O8>=AB8*0.98),"No conflict", IF(OR(R8<0.16,R8>0.2),"Margin conflict", "Price positioning conflict"))) -> No conflict | T8: =IF(S8="No conflict","Approve","Review") -> Approve | U8: =IF(AND(L8="Within margin threshold",M8="Within range"),"No decision priority",IF(V8="Yes","Price positioning","Margin")) -> Margin | V8: No | W8: No | X8: 3.9 | Y8: 4.3 | Z8: 4 | AA8: =MIN(X8:Z8) -> 3.9 | AB8: =AVERAGE(X8:Z8) -> 4.0666667 | AC8: 230 | AD8: =ROUND(AC8*AN8,0) -> 897 | AE8: =AD8/AC8 -> 3.9 | AF8: =IF(AE8<4,"Understocked",IF(AE8<=Model_Controls!$B$27,"Rightly stocked","Overstocked")) -> Understocked | AG8: =IF(AF8="Understocked", "Increase next order stock cover", IF(AF8="Rightly stocked", "Keep next order stock cover", IF(AF8="Overstocked", "Reduce next order stock cover",""))) -> Increase next order stock cover | AH8: 22 | AI8: 46069 | AJ8: =IF(V8="Yes","KVI",IF(AC8<180,"Slow mover","Core")) -> Core | AK8: =MIN(Model_Controls!$B$29-0.005,MAX(Model_Controls!$B$28+0.005,I8+IF(MOD($A8,9)=0,-Model_Controls!$B$10+MOD($A8,2)*0.005,IF(V8="Yes",Model_Controls!$B$6+MOD($A8,4)*Model_Controls!$B$9,IF(AC8<180,Model_Controls!$B$8+MOD($A8,3)*Model_Controls!$B$9,Model_Controls!$B$7+MOD($A8,5)*Model_Controls!$B$9))))) -> 0.185 | AL8: =IF(MOD($A8,9)=0,Model_Controls!$B$14+MOD($A8,4)*Model_Controls!$B$18,IF(V8="Yes",Model_Controls!$B$11+MOD($A8,4)*Model_Controls!$B$15,IF(AC8<180,Model_Controls!$B$13+MOD($A8,4)*Model_Controls!$B$17,Model_Controls!$B$12+MOD($A8,5)*Model_Controls!$B$16))) -> 6.3 | AM8: =H8/(1-I8) -> 3.9761905 | AN8: =MIN(X8:Z8) -> 3.9 | AO8: =AVERAGE(X8:Z8) -> 4.0666667
A9: 1008 | B9: Yogurt Drink 250ml | C9: Dairy | D9: Yogurt | E9: Generic | F9: 250ml | G9: 1.5 | H9: =ROUND(G9*(1-AK9),2) -> 1.28 | I9: =IF(V9="Yes",0.12,0.16) -> 0.16 | J9: =(G9-H9)/G9 -> 0.14666667 | K9: =IF(V9="Yes",(G9-AA9)/AA9,(G9-AB9)/AB9) -> 0.011235955 | L9: =IF(V9="Yes", IF(J9<0.12,"Below margin threshold",IF(J9>0.16,"Above margin threshold","Within margin threshold")), IF(J9<0.16,"Below margin threshold",IF(J9>0.2,"Above margin threshold","Within margin threshold"))) -> Below margin threshold | M9: =IF(V9="Yes", IF((G9-AA9)/AA9>-0.02,"Too expensive",IF((G9-AA9)/AA9<-0.04,"Too cheap","Within range")), IF(G9>AB9,"Too expensive",IF(G9<AB9*0.98,"Too cheap","Within range"))) -> Too expensive | N9: =IF(O9<G9,"Decrease Price",IF(O9>G9,"Increase Price","Keep")) -> Keep | O9: =IF(U9="No decision priority",G9, IF(V9="Yes", MROUND( IF(((AA9*0.98)-H9)/(AA9*0.98)<0.12, H9/(1-0.12), IF(((AA9*0.98)-H9)/(AA9*0.98)>0.16, H9/(1-0.16), AA9*0.98)), 0.05), MROUND( IF(((AB9*0.98)-H9)/(AB9*0.98)<0.16, H9/(1-0.16), IF(((AB9*0.98)-H9)/(AB9*0.98)>0.2, H9/(1-0.2), AB9*0.98)), 0.05))) -> 1.5 | P9: =(O9/G9)-1 -> 0 | Q9: =IF(V9="Yes",(O9-AA9)/AA9,(O9-AB9)/AB9) -> 0.011235955 | R9: =(O9-H9)/O9 -> 0.14666667 | S9: =IF(V9="Yes", IF(AND(R9>=0.12,R9<=0.16,Q9<=-0.02,Q9>=-0.04),"No conflict", IF(OR(Q9>-0.02,Q9<-0.04),"Price positioning conflict", "Margin conflict")), IF(AND(R9>=0.16,R9<=0.2,O9<=AB9,O9>=AB9*0.98),"No conflict", IF(OR(R9<0.16,R9>0.2),"Margin conflict", "Price positioning conflict"))) -> Margin conflict | T9: =IF(S9="No conflict","Approve","Review") -> Review | U9: =IF(AND(L9="Within margin threshold",M9="Within range"),"No decision priority",IF(V9="Yes","Price positioning","Margin")) -> Margin | V9: No | W9: No | X9: 1.4 | Y9: 1.6 | Z9: 1.45 | AA9: =MIN(X9:Z9) -> 1.4 | AB9: =AVERAGE(X9:Z9) -> 1.4833333 | AC9: 500 | AD9: =ROUND(AC9*AN9,0) -> 700 | AE9: =AD9/AC9 -> 1.4 | AF9: =IF(AE9<4,"Understocked",IF(AE9<=Model_Controls!$B$27,"Rightly stocked","Overstocked")) -> Understocked | AG9: =IF(AF9="Understocked", "Increase next order stock cover", IF(AF9="Rightly stocked", "Keep next order stock cover", IF(AF9="Overstocked", "Reduce next order stock cover",""))) -> Increase next order stock cover | AH9: 28 | AI9: 46076 | AJ9: =IF(V9="Yes","KVI",IF(AC9<180,"Slow mover","Core")) -> Core | AK9: =MIN(Model_Controls!$B$29-0.005,MAX(Model_Controls!$B$28+0.005,I9+IF(MOD($A9,9)=0,-Model_Controls!$B$10+MOD($A9,2)*0.005,IF(V9="Yes",Model_Controls!$B$6+MOD($A9,4)*Model_Controls!$B$9,IF(AC9<180,Model_Controls!$B$8+MOD($A9,3)*Model_Controls!$B$9,Model_Controls!$B$7+MOD($A9,5)*Model_Controls!$B$9))))) -> 0.15 | AL9: =IF(MOD($A9,9)=0,Model_Controls!$B$14+MOD($A9,4)*Model_Controls!$B$18,IF(V9="Yes",Model_Controls!$B$11+MOD($A9,4)*Model_Controls!$B$15,IF(AC9<180,Model_Controls!$B$13+MOD($A9,4)*Model_Controls!$B$17,Model_Controls!$B$12+MOD($A9,5)*Model_Controls!$B$16))) -> 8.5 | AM9: =H9/(1-I9) -> 1.5238095 | AN9: =MIN(X9:Z9) -> 1.4 | AO9: =AVERAGE(X9:Z9) -> 1.4833333
A10: 1009 | B10: Yogurt Drink 1L | C10: Dairy | D10: Yogurt | E10: Generic | F10: 1L | G10: 3.8 | H10: =ROUND(G10*(1-AK10),2) -> 3.06 | I10: =IF(V10="Yes",0.12,0.16) -> 0.16 | J10: =(G10-H10)/G10 -> 0.19473684 | K10: =IF(V10="Yes",(G10-AA10)/AA10,(G10-AB10)/AB10) -> 0.013333333 | L10: =IF(V10="Yes", IF(J10<0.12,"Below margin threshold",IF(J10>0.16,"Above margin threshold","Within margin threshold")), IF(J10<0.16,"Below margin threshold",IF(J10>0.2,"Above margin threshold","Within margin threshold"))) -> Within margin threshold | M10: =IF(V10="Yes", IF((G10-AA10)/AA10>-0.02,"Too expensive",IF((G10-AA10)/AA10<-0.04,"Too cheap","Within range")), IF(G10>AB10,"Too expensive",IF(G10<AB10*0.98,"Too cheap","Within range"))) -> Too expensive | N10: =IF(O10<G10,"Decrease Price",IF(O10>G10,"Increase Price","Keep")) -> Decrease Price | O10: =IF(U10="No decision priority",G10, IF(V10="Yes", MROUND( IF(((AA10*0.98)-H10)/(AA10*0.98)<0.12, H10/(1-0.12), IF(((AA10*0.98)-H10)/(AA10*0.98)>0.16, H10/(1-0.16), AA10*0.98)), 0.05), MROUND( IF(((AB10*0.98)-H10)/(AB10*0.98)<0.16, H10/(1-0.16), IF(((AB10*0.98)-H10)/(AB10*0.98)>0.2, H10/(1-0.2), AB10*0.98)), 0.05))) -> 3.65 | P10: =(O10/G10)-1 -> -0.039473684 | Q10: =IF(V10="Yes",(O10-AA10)/AA10,(O10-AB10)/AB10) -> -0.026666667 | R10: =(O10-H10)/O10 -> 0.16164384 | S10: =IF(V10="Yes", IF(AND(R10>=0.12,R10<=0.16,Q10<=-0.02,Q10>=-0.04),"No conflict", IF(OR(Q10>-0.02,Q10<-0.04),"Price positioning conflict", "Margin conflict")), IF(AND(R10>=0.16,R10<=0.2,O10<=AB10,O10>=AB10*0.98),"No conflict", IF(OR(R10<0.16,R10>0.2),"Margin conflict", "Price positioning conflict"))) -> Price positioning conflict | T10: =IF(S10="No conflict","Approve","Review") -> Review | U10: =IF(AND(L10="Within margin threshold",M10="Within range"),"No decision priority",IF(V10="Yes","Price positioning","Margin")) -> Margin | V10: No | W10: No | X10: 3.6 | Y10: 3.95 | Z10: 3.7 | AA10: =MIN(X10:Z10) -> 3.6 | AB10: =AVERAGE(X10:Z10) -> 3.75 | AC10: 260 | AD10: =ROUND(AC10*AN10,0) -> 936 | AE10: =AD10/AC10 -> 3.6 | AF10: =IF(AE10<4,"Understocked",IF(AE10<=Model_Controls!$B$27,"Rightly stocked","Overstocked")) -> Understocked | AG10: =IF(AF10="Understocked", "Increase next order stock cover", IF(AF10="Rightly stocked", "Keep next order stock cover", IF(AF10="Overstocked", "Reduce next order stock cover",""))) -> Increase next order stock cover | AH10: 22 | AI10: 46067 | AJ10: =IF(V10="Yes","KVI",IF(AC10<180,"Slow mover","Core")) -> Core | AK10: =MIN(Model_Controls!$B$29-0.005,MAX(Model_Controls!$B$28+0.005,I10+IF(MOD($A10,9)=0,-Model_Controls!$B$10+MOD($A10,2)*0.005,IF(V10="Yes",Model_Controls!$B$6+MOD($A10,4)*Model_Controls!$B$9,IF(AC10<180,Model_Controls!$B$8+MOD($A10,3)*Model_Controls!$B$9,Model_Controls!$B$7+MOD($A10,5)*Model_Controls!$B$9))))) -> 0.195 | AL10: =IF(MOD($A10,9)=0,Model_Controls!$B$14+MOD($A10,4)*Model_Controls!$B$18,IF(V10="Yes",Model_Controls!$B$11+MOD($A10,4)*Model_Controls!$B$15,IF(AC10<180,Model_Controls!$B$13+MOD($A10,4)*Model_Controls!$B$17,Model_Controls!$B$12+MOD($A10,5)*Model_Controls!$B$16))) -> 7.1 | AM10: =H10/(1-I10) -> 3.6428571 | AN10: =MIN(X10:Z10) -> 3.6 | AO10: =AVERAGE(X10:Z10) -> 3.75
A11: 1010 | B11: Butter 250g | C11: Dairy | D11: Butter | E11: Generic | F11: 250g | G11: 4.8 | H11: =ROUND(G11*(1-AK11),2) -> 4.08 | I11: =IF(V11="Yes",0.12,0.16) -> 0.12 | J11: =(G11-H11)/G11 -> 0.15 | K11: =IF(V11="Yes",(G11-AA11)/AA11,(G11-AB11)/AB11) -> 0.054945055 | L11: =IF(V11="Yes", IF(J11<0.12,"Below margin threshold",IF(J11>0.16,"Above margin threshold","Within margin threshold")), IF(J11<0.16,"Below margin threshold",IF(J11>0.2,"Above margin threshold","Within margin threshold"))) -> Within margin threshold | M11: =IF(V11="Yes", IF((G11-AA11)/AA11>-0.02,"Too expensive",IF((G11-AA11)/AA11<-0.04,"Too cheap","Within range")), IF(G11>AB11,"Too expensive",IF(G11<AB11*0.98,"Too cheap","Within range"))) -> Too expensive | N11: =IF(O11<G11,"Decrease Price",IF(O11>G11,"Increase Price","Keep")) -> Decrease Price | O11: =IF(U11="No decision priority",G11, IF(V11="Yes", MROUND( IF(((AA11*0.98)-H11)/(AA11*0.98)<0.12, H11/(1-0.12), IF(((AA11*0.98)-H11)/(AA11*0.98)>0.16, H11/(1-0.16), AA11*0.98)), 0.05), MROUND( IF(((AB11*0.98)-H11)/(AB11*0.98)<0.16, H11/(1-0.16), IF(((AB11*0.98)-H11)/(AB11*0.98)>0.2, H11/(1-0.2), AB11*0.98)), 0.05))) -> 4.65 | P11: =(O11/G11)-1 -> -0.03125 | Q11: =IF(V11="Yes",(O11-AA11)/AA11,(O11-AB11)/AB11) -> 0.021978022 | R11: =(O11-H11)/O11 -> 0.12258065 | S11: =IF(V11="Yes", IF(AND(R11>=0.12,R11<=0.16,Q11<=-0.02,Q11>=-0.04),"No conflict", IF(OR(Q11>-0.02,Q11<-0.04),"Price positioning conflict", "Margin conflict")), IF(AND(R11>=0.16,R11<=0.2,O11<=AB11,O11>=AB11*0.98),"No conflict", IF(OR(R11<0.16,R11>0.2),"Margin conflict", "Price positioning conflict"))) -> Price positioning conflict | T11: =IF(S11="No conflict","Approve","Review") -> Review | U11: =IF(AND(L11="Within margin threshold",M11="Within range"),"No decision priority",IF(V11="Yes","Price positioning","Margin")) -> Price positioning | V11: Yes | W11: No | X11: 4.55 | Y11: 5.1 | Z11: 4.7 | AA11: =MIN(X11:Z11) -> 4.55 | AB11: =AVERAGE(X11:Z11) -> 4.7833333 | AC11: 360 | AD11: =ROUND(AC11*AN11,0) -> 1638 | AE11: =AD11/AC11 -> 4.55 | AF11: =IF(AE11<4,"Understocked",IF(AE11<=Model_Controls!$B$27,"Rightly stocked","Overstocked")) -> Rightly stocked | AG11: =IF(AF11="Understocked", "Increase next order stock cover", IF(AF11="Rightly stocked", "Keep next order stock cover", IF(AF11="Overstocked", "Reduce next order stock cover",""))) -> Keep next order stock cover | AH11: 26 | AI11: 46073 | AJ11: =IF(V11="Yes","KVI",IF(AC11<180,"Slow mover","Core")) -> KVI | AK11: =MIN(Model_Controls!$B$29-0.005,MAX(Model_Controls!$B$28+0.005,I11+IF(MOD($A11,9)=0,-Model_Controls!$B$10+MOD($A11,2)*0.005,IF(V11="Yes",Model_Controls!$B$6+MOD($A11,4)*Model_Controls!$B$9,IF(AC11<180,Model_Controls!$B$8+MOD($A11,3)*Model_Controls!$B$9,Model_Controls!$B$7+MOD($A11,5)*Model_Controls!$B$9))))) -> 0.15 | AL11: =IF(MOD($A11,9)=0,Model_Controls!$B$14+MOD($A11,4)*Model_Controls!$B$18,IF(V11="Yes",Model_Controls!$B$11+MOD($A11,4)*Model_Controls!$B$15,IF(AC11<180,Model_Controls!$B$13+MOD($A11,4)*Model_Controls!$B$17,Model_Controls!$B$12+MOD($A11,5)*Model_Controls!$B$16))) -> 5.5 | AM11: =H11/(1-I11) -> 4.6363636 | AN11: =MIN(X11:Z11) -> 4.55 | AO11: =AVERAGE(X11:Z11) -> 4.7833333
A12: 1011 | B12: Butter 500g | C12: Dairy | D12: Butter | E12: Generic | F12: 500g | G12: 8.9 | H12: =ROUND(G12*(1-AK12),2) -> 7.34 | I12: =IF(V12="Yes",0.12,0.16) -> 0.16 | J12: =(G12-H12)/G12 -> 0.1752809 | K12: =IF(V12="Yes",(G12-AA12)/AA12,(G12-AB12)/AB12) -> 0 | L12: =IF(V12="Yes", IF(J12<0.12,"Below margin threshold",IF(J12>0.16,"Above margin threshold","Within margin threshold")), IF(J12<0.16,"Below margin threshold",IF(J12>0.2,"Above margin threshold","Within margin threshold"))) -> Within margin threshold | M12: =IF(V12="Yes", IF((G12-AA12)/AA12>-0.02,"Too expensive",IF((G12-AA12)/AA12<-0.04,"Too cheap","Within range")), IF(G12>AB12,"Too expensive",IF(G12<AB12*0.98,"Too cheap","Within range"))) -> Within range | N12: =IF(O12<G12,"Decrease Price",IF(O12>G12,"Increase Price","Keep")) -> Keep | O12: =IF(U12="No decision priority",G12, IF(V12="Yes", MROUND( IF(((AA12*0.98)-H12)/(AA12*0.98)<0.12, H12/(1-0.12), IF(((AA12*0.98)-H12)/(AA12*0.98)>0.16, H12/(1-0.16), AA12*0.98)), 0.05), MROUND( IF(((AB12*0.98)-H12)/(AB12*0.98)<0.16, H12/(1-0.16), IF(((AB12*0.98)-H12)/(AB12*0.98)>0.2, H12/(1-0.2), AB12*0.98)), 0.05))) -> 8.9 | P12: =(O12/G12)-1 -> 0 | Q12: =IF(V12="Yes",(O12-AA12)/AA12,(O12-AB12)/AB12) -> 0 | R12: =(O12-H12)/O12 -> 0.1752809 | S12: =IF(V12="Yes", IF(AND(R12>=0.12,R12<=0.16,Q12<=-0.02,Q12>=-0.04),"No conflict", IF(OR(Q12>-0.02,Q12<-0.04),"Price positioning conflict", "Margin conflict")), IF(AND(R12>=0.16,R12<=0.2,O12<=AB12,O12>=AB12*0.98),"No conflict", IF(OR(R12<0.16,R12>0.2),"Margin conflict", "Price positioning conflict"))) -> No conflict | T12: =IF(S12="No conflict","Approve","Review") -> Approve | U12: =IF(AND(L12="Within margin threshold",M12="Within range"),"No decision priority",IF(V12="Yes","Price positioning","Margin")) -> No decision priority | V12: No | W12: No | X12: 8.6 | Y12: 9.35 | Z12: 8.75 | AA12: =MIN(X12:Z12) -> 8.6 | AB12: =AVERAGE(X12:Z12) -> 8.9 | AC12: 240 | AD12: =ROUND(AC12*AN12,0) -> 2064 | AE12: =AD12/AC12 -> 8.6 | AF12: =IF(AE12<4,"Understocked",IF(AE12<=Model_Controls!$B$27,"Rightly stocked","Overstocked")) -> Overstocked | AG12: =IF(AF12="Understocked", "Increase next order stock cover", IF(AF12="Rightly stocked", "Keep next order stock cover", IF(AF12="Overstocked", "Reduce next order stock cover",""))) -> Reduce next order stock cover | AH12: 26 | AI12: 46073 | AJ12: =IF(V12="Yes","KVI",IF(AC12<180,"Slow mover","Core")) -> Core | AK12: =MIN(Model_Controls!$B$29-0.005,MAX(Model_Controls!$B$28+0.005,I12+IF(MOD($A12,9)=0,-Model_Controls!$B$10+MOD($A12,2)*0.005,IF(V12="Yes",Model_Controls!$B$6+MOD($A12,4)*Model_Controls!$B$9,IF(AC12<180,Model_Controls!$B$8+MOD($A12,3)*Model_Controls!$B$9,Model_Controls!$B$7+MOD($A12,5)*Model_Controls!$B$9))))) -> 0.175 | AL12: =IF(MOD($A12,9)=0,Model_Controls!$B$14+MOD($A12,4)*Model_Controls!$B$18,IF(V12="Yes",Model_Controls!$B$11+MOD($A12,4)*Model_Controls!$B$15,IF(AC12<180,Model_Controls!$B$13+MOD($A12,4)*Model_Controls!$B$17,Model_Controls!$B$12+MOD($A12,5)*Model_Controls!$B$16))) -> 5.9 | AM12: =H12/(1-I12) -> 8.7380952 | AN12: =MIN(X12:Z12) -> 8.6 | AO12: =AVERAGE(X12:Z12) -> 8.9
A13: 1012 | B13: Margarine 250g | C13: Dairy | D13: Margarine | E13: Generic | F13: 250g | G13: 2.2 | H13: =ROUND(G13*(1-AK13),2) -> 1.79 | I13: =IF(V13="Yes",0.12,0.16) -> 0.16 | J13: =(G13-H13)/G13 -> 0.18636364 | K13: =IF(V13="Yes",(G13-AA13)/AA13,(G13-AB13)/AB13) -> 2.0185873e-16 | L13: =IF(V13="Yes", IF(J13<0.12,"Below margin threshold",IF(J13>0.16,"Above margin threshold","Within margin threshold")), IF(J13<0.16,"Below margin threshold",IF(J13>0.2,"Above margin threshold","Within margin threshold"))) -> Within margin threshold | M13: =IF(V13="Yes", IF((G13-AA13)/AA13>-0.02,"Too expensive",IF((G13-AA13)/AA13<-0.04,"Too cheap","Within range")), IF(G13>AB13,"Too expensive",IF(G13<AB13*0.98,"Too cheap","Within range"))) -> Within range | N13: =IF(O13<G13,"Decrease Price",IF(O13>G13,"Increase Price","Keep")) -> Keep | O13: =IF(U13="No decision priority",G13, IF(V13="Yes", MROUND( IF(((AA13*0.98)-H13)/(AA13*0.98)<0.12, H13/(1-0.12), IF(((AA13*0.98)-H13)/(AA13*0.98)>0.16, H13/(1-0.16), AA13*0.98)), 0.05), MROUND( IF(((AB13*0.98)-H13)/(AB13*0.98)<0.16, H13/(1-0.16), IF(((AB13*0.98)-H13)/(AB13*0.98)>0.2, H13/(1-0.2), AB13*0.98)), 0.05))) -> 2.2 | P13: =(O13/G13)-1 -> 0 | Q13: =IF(V13="Yes",(O13-AA13)/AA13,(O13-AB13)/AB13) -> 2.0185873e-16 | R13: =(O13-H13)/O13 -> 0.18636364 | S13: =IF(V13="Yes", IF(AND(R13>=0.12,R13<=0.16,Q13<=-0.02,Q13>=-0.04),"No conflict", IF(OR(Q13>-0.02,Q13<-0.04),"Price positioning conflict", "Margin conflict")), IF(AND(R13>=0.16,R13<=0.2,O13<=AB13,O13>=AB13*0.98),"No conflict", IF(OR(R13<0.16,R13>0.2),"Margin conflict", "Price positioning conflict"))) -> No conflict | T13: =IF(S13="No conflict","Approve","Review") -> Approve | U13: =IF(AND(L13="Within margin threshold",M13="Within range"),"No decision priority",IF(V13="Yes","Price positioning","Margin")) -> No decision priority | V13: No | W13: No | X13: 2.1 | Y13: 2.35 | Z13: 2.15 | AA13: =MIN(X13:Z13) -> 2.1 | AB13: =AVERAGE(X13:Z13) -> 2.2 | AC13: 190 | AD13: =ROUND(AC13*AN13,0) -> 399 | AE13: =AD13/AC13 -> 2.1 | AF13: =IF(AE13<4,"Understocked",IF(AE13<=Model_Controls!$B$27,"Rightly stocked","Overstocked")) -> Understocked | AG13: =IF(AF13="Understocked", "Increase next order stock cover", IF(AF13="Rightly stocked", "Keep next order stock cover", IF(AF13="Overstocked", "Reduce next order stock cover",""))) -> Increase next order stock cover | AH13: 22 | AI13: 46064 | AJ13: =IF(V13="Yes","KVI",IF(AC13<180,"Slow mover","Core")) -> Core | AK13: =MIN(Model_Controls!$B$29-0.005,MAX(Model_Controls!$B$28+0.005,I13+IF(MOD($A13,9)=0,-Model_Controls!$B$10+MOD($A13,2)*0.005,IF(V13="Yes",Model_Controls!$B$6+MOD($A13,4)*Model_Controls!$B$9,IF(AC13<180,Model_Controls!$B$8+MOD($A13,3)*Model_Controls!$B$9,Model_Controls!$B$7+MOD($A13,5)*Model_Controls!$B$9))))) -> 0.185 | AL13: =IF(MOD($A13,9)=0,Model_Controls!$B$14+MOD($A13,4)*Model_Controls!$B$18,IF(V13="Yes",Model_Controls!$B$11+MOD($A13,4)*Model_Controls!$B$15,IF(AC13<180,Model_Controls!$B$13+MOD($A13,4)*Model_Controls!$B$17,Model_Controls!$B$12+MOD($A13,5)*Model_Controls!$B$16))) -> 6.3 | AM13: =H13/(1-I13) -> 2.1309524 | AN13: =MIN(X13:Z13) -> 2.1 | AO13: =AVERAGE(X13:Z13) -> 2.2
... A41: 1040 | B41: Organic Milk 1L | C41: Dairy | D41: Milk | E41: Generic | F41: 1L | G41: 3.4 | H41: =ROUND(G41*(1-AK41),2) -> 2.84 | I41: =IF(V41="Yes",0.12,0.16) -> 0.16 | J41: =(G41-H41)/G41 -> 0.16470588 | K41: =IF(V41="Yes",(G41-AA41)/AA41,(G41-AB41)/AB41) -> -0.0048780488 | L41: =IF(V41="Yes", IF(J41<0.12,"Below margin threshold",IF(J41>0.16,"Above margin threshold","Within margin threshold")), IF(J41<0.16,"Below margin threshold",IF(J41>0.2,"Above margin threshold","Within margin threshold"))) -> Within margin threshold | M41: =IF(V41="Yes", IF((G41-AA41)/AA41>-0.02,"Too expensive",IF((G41-AA41)/AA41<-0.04,"Too cheap","Within range")), IF(G41>AB41,"Too expensive",IF(G41<AB41*0.98,"Too cheap","Within range"))) -> Within range | N41: =IF(O41<G41,"Decrease Price",IF(O41>G41,"Increase Price","Keep")) -> Keep | O41: =IF(U41="No decision priority",G41, IF(V41="Yes", MROUND( IF(((AA41*0.98)-H41)/(AA41*0.98)<0.12, H41/(1-0.12), IF(((AA41*0.98)-H41)/(AA41*0.98)>0.16, H41/(1-0.16), AA41*0.98)), 0.05), MROUND( IF(((AB41*0.98)-H41)/(AB41*0.98)<0.16, H41/(1-0.16), IF(((AB41*0.98)-H41)/(AB41*0.98)>0.2, H41/(1-0.2), AB41*0.98)), 0.05))) -> 3.4 | P41: =(O41/G41)-1 -> 0 | Q41: =IF(V41="Yes",(O41-AA41)/AA41,(O41-AB41)/AB41) -> -0.0048780488 | R41: =(O41-H41)/O41 -> 0.16470588 | S41: =IF(V41="Yes", IF(AND(R41>=0.12,R41<=0.16,Q41<=-0.02,Q41>=-0.04),"No conflict", IF(OR(Q41>-0.02,Q41<-0.04),"Price positioning conflict", "Margin conflict")), IF(AND(R41>=0.16,R41<=0.2,O41<=AB41,O41>=AB41*0.98),"No conflict", IF(OR(R41<0.16,R41>0.2),"Margin conflict", "Price positioning conflict"))) -> No conflict | T41: =IF(S41="No conflict","Approve","Review") -> Approve | U41: =IF(AND(L41="Within margin threshold",M41="Within range"),"No decision priority",IF(V41="Yes","Price positioning","Margin")) -> No decision priority | V41: No | W41: No | X41: 3.25 | Y41: 3.7 | Z41: 3.3 | AA41: =MIN(X41:Z41) -> 3.25 | AB41: =AVERAGE(X41:Z41) -> 3.4166667 | AC41: 180 | AD41: =ROUND(AC41*AN41,0) -> 585 | AE41: =AD41/AC41 -> 3.25 | AF41: =IF(AE41<4,"Understocked",IF(AE41<=Model_Controls!$B$27,"Rightly stocked","Overstocked")) -> Understocked | AG41: =IF(AF41="Understocked", "Increase next order stock cover", IF(AF41="Rightly stocked", "Keep next order stock cover", IF(AF41="Overstocked", "Reduce next order stock cover",""))) -> Increase next order stock cover | AH41: 22 | AI41: 46068 | AJ41: =IF(V41="Yes","KVI",IF(AC41<180,"Slow mover","Core")) -> Core | AK41: =MIN(Model_Controls!$B$29-0.005,MAX(Model_Controls!$B$28+0.005,I41+IF(MOD($A41,9)=0,-Model_Controls!$B$10+MOD($A41,2)*0.005,IF(V41="Yes",Model_Controls!$B$6+MOD($A41,4)*Model_Controls!$B$9,IF(AC41<180,Model_Controls!$B$8+MOD($A41,3)*Model_Controls!$B$9,Model_Controls!$B$7+MOD($A41,5)*Model_Controls!$B$9))))) -> 0.165 | AL41: =IF(MOD($A41,9)=0,Model_Controls!$B$14+MOD($A41,4)*Model_Controls!$B$18,IF(V41="Yes",Model_Controls!$B$11+MOD($A41,4)*Model_Controls!$B$15,IF(AC41<180,Model_Controls!$B$13+MOD($A41,4)*Model_Controls!$B$17,Model_Controls!$B$12+MOD($A41,5)*Model_Controls!$B$16))) -> 5.5 | AM41: =H41/(1-I41) -> 3.3809524 | AN41: =MIN(X41:Z41) -> 3.25 | AO41: =AVERAGE(X41:Z41) -> 3.4166667

Sheet Agent simulation
A1: Scenario | B1: Sku | C1: Product name | D1: KVI Flag | E1: Simulated selling price | F1: Cost | G1: Lowest competitor's price | H1: Average market price | I1: Stock cover | J1: Current GM% | K1: Margin flag | L1: Price positioning | M1: Decision priority | N1: Suggested price | O1: Recommended pricing action | P1: New GM% | Q1: New positioning | R1: New Margin flag | S1: Conflict type | T1: Action | U1: Effective starting price | V1: Current difference vs bechmark | W1: New Difference Vs benchmark | X1: Elasticity band | Y1: Reaction intensity | Z1: pricing insight
A2: A decrease in KVI RSP | B2: 1001 | C2: =VLOOKUP(B2,'Pricing Engine V1'!$A:$B,2,FALSE) -> Milk 1L | D2: =VLOOKUP(B2,'Pricing Engine V1'!$A:$V,22,FALSE) -> Yes | E2: 2.6 | F2: =VLOOKUP(B2,'Pricing Engine V1'!$A:$H,8,FALSE) -> 2.15 | G2: =VLOOKUP(B2,'Pricing Engine V1'!$A:$AA,27,FALSE) -> 2.35 | H2: =VLOOKUP(B2,'Pricing Engine V1'!$A:$AB,28,FALSE) -> 2.4333333 | I2: =VLOOKUP(B2,'Pricing Engine V1'!$A:$AE,31,FALSE) -> 2.35 | J2: =IFERROR((U2-F2)/U2,"") -> 0.17307692 | K2: =IF(OR(U2="",F2=""),"",IF(D2="Yes",IF(J2<0.12,"Below margin threshold",IF(J2<=0.16,"Within margin threshold","Above margin threshold")),IF(J2<0.16,"Below margin threshold",IF(J2<=0.2,"Within margin threshold","Above margin threshold")))) -> Above margin threshold | L2: =IF(U2="","",IF(D2="Yes",IF(G2="","",IF((U2-G2)/G2>-0.02,"Too expensive",IF((U2-G2)/G2<-0.04,"Too cheap","Within range"))),IF(H2="","",IF(U2>H2,"Too expensive",IF(U2<H2*0.98,"Too cheap","Within range"))))) -> Too expensive | M2: =IF(OR(K2="",L2=""),"",IF(AND(K2="Within margin threshold",L2="Within range"),"No decision priority",IF(D2="Yes","Price positioning","Margin"))) -> Price positioning | N2: =IF(M2="No decision priority",U2, IF(D2="Yes", MROUND( IF(((G2*0.98)-F2)/(G2*0.98)<0.12, F2/(1-0.12), IF(((G2*0.98)-F2)/(G2*0.98)>0.16, F2/(1-0.16), G2*0.98)), 0.05), MROUND( IF(((H2*0.98)-F2)/(H2*0.98)<0.16, F2/(1-0.16), IF(((H2*0.98)-F2)/(H2*0.98)>0.2, F2/(1-0.2), H2*0.98)), 0.05))) -> 2.45 | O2: =IF(OR(N2="",U2=""),"",IF(N2<U2,"Decrease Price",IF(N2>U2,"Increase Price","Keep"))) -> Decrease Price | P2: =IFERROR((N2-F2)/N2,"") -> 0.12244898 | Q2: =IF(N2="","",IF(D2="Yes",IF(G2="","",IF((N2-G2)/G2>-0.02,"Too expensive",IF((N2-G2)/G2<-0.04,"Too cheap","Within range"))),IF(H2="","",IF(N2>H2,"Too expensive",IF(N2<H2*0.98,"Too cheap","Within range"))))) -> Too expensive | R2: =IF(OR(N2="",P2=""),"",IF(D2="Yes",IF(P2<0.12,"Below margin threshold",IF(P2<=0.16,"Within margin threshold","Above margin threshold")),IF(P2<0.16,"Below margin threshold",IF(P2<=0.2,"Within margin threshold","Above margin threshold")))) -> Within margin threshold | S2: =IF(AND(R2="Within margin threshold",Q2="Within range"),"No conflict",IF(D2="Yes",IF(Q2<>"Within range","Price positioning conflict","Margin conflict"),IF(R2<>"Within margin threshold","Margin conflict","Price positioning conflict"))) -> Price positioning conflict | T2: =IF(S2="No conflict","Approve","Review") -> Review | U2: =IF(E2<>"",E2,VLOOKUP(B2,'Pricing Engine V1'!$A:$G,7,FALSE)) -> 2.6 | V2: =IF(U2="","",IF(D2="Yes",(U2-G2)/G2,(U2-H2)/H2)) -> 0.10638298 | W2: =IF(N2="","",IF(D2="Yes",(N2-G2)/G2,(N2-H2)/H2)) -> 0.042553191 | X2: High | Y2: =IF(X2="High","High urgency",IF(X2="Medium","Balanced","Low urgency")) -> High urgency | Z2: =IF(Y2="High urgency","Immediate reaction required", IF(Y2="Low urgency","Monitor and adjust cautiously", "Standard pricing adjustment")) -> Immediate reaction required
A3: An increase in KVI RSP | B3: 1002 | C3: =VLOOKUP(B3,'Pricing Engine V1'!$A:$B,2,FALSE) -> Milk 2L | D3: =VLOOKUP(B3,'Pricing Engine V1'!$A:$V,22,FALSE) -> Yes | E3: 4.9 | F3: =VLOOKUP(B3,'Pricing Engine V1'!$A:$H,8,FALSE) -> 4.08 | G3: =VLOOKUP(B3,'Pricing Engine V1'!$A:$AA,27,FALSE) -> 4.6 | H3: =VLOOKUP(B3,'Pricing Engine V1'!$A:$AB,28,FALSE) -> 4.75 | I3: =VLOOKUP(B3,'Pricing Engine V1'!$A:$AE,31,FALSE) -> 4.6 | J3: =IFERROR((U3-F3)/U3,"") -> 0.16734694 | K3: =IF(OR(U3="",F3=""),"",IF(D3="Yes",IF(J3<0.12,"Below margin threshold",IF(J3<=0.16,"Within margin threshold","Above margin threshold")),IF(J3<0.16,"Below margin threshold",IF(J3<=0.2,"Within margin threshold","Above margin threshold")))) -> Above margin threshold | L3: =IF(U3="","",IF(D3="Yes",IF(G3="","",IF((U3-G3)/G3>-0.02,"Too expensive",IF((U3-G3)/G3<-0.04,"Too cheap","Within range"))),IF(H3="","",IF(U3>H3,"Too expensive",IF(U3<H3*0.98,"Too cheap","Within range"))))) -> Too expensive | M3: =IF(OR(K3="",L3=""),"",IF(AND(K3="Within margin threshold",L3="Within range"),"No decision priority",IF(D3="Yes","Price positioning","Margin"))) -> Price positioning | N3: =IF(M3="No decision priority",U3, IF(D3="Yes", MROUND( IF(((G3*0.98)-F3)/(G3*0.98)<0.12, F3/(1-0.12), IF(((G3*0.98)-F3)/(G3*0.98)>0.16, F3/(1-0.16), G3*0.98)), 0.05), MROUND( IF(((H3*0.98)-F3)/(H3*0.98)<0.16, F3/(1-0.16), IF(((H3*0.98)-F3)/(H3*0.98)>0.2, F3/(1-0.2), H3*0.98)), 0.05))) -> 4.65 | O3: =IF(OR(N3="",U3=""),"",IF(N3<U3,"Decrease Price",IF(N3>U3,"Increase Price","Keep"))) -> Decrease Price | P3: =IFERROR((N3-F3)/N3,"") -> 0.12258065 | Q3: =IF(N3="","",IF(D3="Yes",IF(G3="","",IF((N3-G3)/G3>-0.02,"Too expensive",IF((N3-G3)/G3<-0.04,"Too cheap","Within range"))),IF(H3="","",IF(N3>H3,"Too expensive",IF(N3<H3*0.98,"Too cheap","Within range"))))) -> Too expensive | R3: =IF(OR(N3="",P3=""),"",IF(D3="Yes",IF(P3<0.12,"Below margin threshold",IF(P3<=0.16,"Within margin threshold","Above margin threshold")),IF(P3<0.16,"Below margin threshold",IF(P3<=0.2,"Within margin threshold","Above margin threshold")))) -> Within margin threshold | S3: =IF(AND(R3="Within margin threshold",Q3="Within range"),"No conflict",IF(D3="Yes",IF(Q3<>"Within range","Price positioning conflict","Margin conflict"),IF(R3<>"Within margin threshold","Margin conflict","Price positioning conflict"))) -> Price positioning conflict | T3: =IF(S3="No conflict","Approve","Review") -> Review | U3: =IF(E3<>"",E3,VLOOKUP(B3,'Pricing Engine V1'!$A:$G,7,FALSE)) -> 4.9 | V3: =IF(U3="","",IF(D3="Yes",(U3-G3)/G3,(U3-H3)/H3)) -> 0.065217391 | W3: =IF(N3="","",IF(D3="Yes",(N3-G3)/G3,(N3-H3)/H3)) -> 0.010869565 | X3: High | Y3: =IF(X3="High","High urgency",IF(X3="Medium","Balanced","Low urgency")) -> High urgency | Z3: =IF(Y3="High urgency","Immediate reaction required", IF(Y3="Low urgency","Monitor and adjust cautiously", "Standard pricing adjustment")) -> Immediate reaction required
A4: Non-KVI item, RSP increase | B4: 1003 | C4: =VLOOKUP(B4,'Pricing Engine V1'!$A:$B,2,FALSE) -> Skim Milk 1L | D4: =VLOOKUP(B4,'Pricing Engine V1'!$A:$V,22,FALSE) -> No | E4: 2.8 | F4: =VLOOKUP(B4,'Pricing Engine V1'!$A:$H,8,FALSE) -> 2.09 | G4: =VLOOKUP(B4,'Pricing Engine V1'!$A:$AA,27,FALSE) -> 2.45 | H4: =VLOOKUP(B4,'Pricing Engine V1'!$A:$AB,28,FALSE) -> 2.55 | I4: =VLOOKUP(B4,'Pricing Engine V1'!$A:$AE,31,FALSE) -> 2.4512195 | J4: =IFERROR((U4-F4)/U4,"") -> 0.25357143 | K4: =IF(OR(U4="",F4=""),"",IF(D4="Yes",IF(J4<0.12,"Below margin threshold",IF(J4<=0.16,"Within margin threshold","Above margin threshold")),IF(J4<0.16,"Below margin threshold",IF(J4<=0.2,"Within margin threshold","Above margin threshold")))) -> Above margin threshold | L4: =IF(U4="","",IF(D4="Yes",IF(G4="","",IF((U4-G4)/G4>-0.02,"Too expensive",IF((U4-G4)/G4<-0.04,"Too cheap","Within range"))),IF(H4="","",IF(U4>H4,"Too expensive",IF(U4<H4*0.98,"Too cheap","Within range"))))) -> Too expensive | M4: =IF(OR(K4="",L4=""),"",IF(AND(K4="Within margin threshold",L4="Within range"),"No decision priority",IF(D4="Yes","Price positioning","Margin"))) -> Margin | N4: =IF(M4="No decision priority",U4, IF(D4="Yes", MROUND( IF(((G4*0.98)-F4)/(G4*0.98)<0.12, F4/(1-0.12), IF(((G4*0.98)-F4)/(G4*0.98)>0.16, F4/(1-0.16), G4*0.98)), 0.05), MROUND( IF(((H4*0.98)-F4)/(H4*0.98)<0.16, F4/(1-0.16), IF(((H4*0.98)-F4)/(H4*0.98)>0.2, F4/(1-0.2), H4*0.98)), 0.05))) -> 2.5 | O4: =IF(OR(N4="",U4=""),"",IF(N4<U4,"Decrease Price",IF(N4>U4,"Increase Price","Keep"))) -> Decrease Price | P4: =IFERROR((N4-F4)/N4,"") -> 0.164 | Q4: =IF(N4="","",IF(D4="Yes",IF(G4="","",IF((N4-G4)/G4>-0.02,"Too expensive",IF((N4-G4)/G4<-0.04,"Too cheap","Within range"))),IF(H4="","",IF(N4>H4,"Too expensive",IF(N4<H4*0.98,"Too cheap","Within range"))))) -> Within range | R4: =IF(OR(N4="",P4=""),"",IF(D4="Yes",IF(P4<0.12,"Below margin threshold",IF(P4<=0.16,"Within margin threshold","Above margin threshold")),IF(P4<0.16,"Below margin threshold",IF(P4<=0.2,"Within margin threshold","Above margin threshold")))) -> Within margin threshold | S4: =IF(AND(R4="Within margin threshold",Q4="Within range"),"No conflict",IF(D4="Yes",IF(Q4<>"Within range","Price positioning conflict","Margin conflict"),IF(R4<>"Within margin threshold","Margin conflict","Price positioning conflict"))) -> No conflict | T4: =IF(S4="No conflict","Approve","Review") -> Approve | U4: =IF(E4<>"",E4,VLOOKUP(B4,'Pricing Engine V1'!$A:$G,7,FALSE)) -> 2.8 | V4: =IF(U4="","",IF(D4="Yes",(U4-G4)/G4,(U4-H4)/H4)) -> 0.098039216 | W4: =IF(N4="","",IF(D4="Yes",(N4-G4)/G4,(N4-H4)/H4)) -> -0.019607843 | X4: Medium | Y4: =IF(X4="High","High urgency",IF(X4="Medium","Balanced","Low urgency")) -> Balanced | Z4: =IF(Y4="High urgency","Immediate reaction required", IF(Y4="Low urgency","Monitor and adjust cautiously", "Standard pricing adjustment")) -> Standard pricing adjustment
A5: Non-KVI item, RSP decrease | B5: 1004 | C5: =VLOOKUP(B5,'Pricing Engine V1'!$A:$B,2,FALSE) -> Chocolate Milk 1L | D5: =VLOOKUP(B5,'Pricing Engine V1'!$A:$V,22,FALSE) -> No | E5: 3.1 | F5: =VLOOKUP(B5,'Pricing Engine V1'!$A:$H,8,FALSE) -> 2.58 | G5: =VLOOKUP(B5,'Pricing Engine V1'!$A:$AA,27,FALSE) -> 3.1 | H5: =VLOOKUP(B5,'Pricing Engine V1'!$A:$AB,28,FALSE) -> 3.2 | I5: =VLOOKUP(B5,'Pricing Engine V1'!$A:$AE,31,FALSE) -> 3.1 | J5: =IFERROR((U5-F5)/U5,"") -> 0.16774194 | K5: =IF(OR(U5="",F5=""),"",IF(D5="Yes",IF(J5<0.12,"Below margin threshold",IF(J5<=0.16,"Within margin threshold","Above margin threshold")),IF(J5<0.16,"Below margin threshold",IF(J5<=0.2,"Within margin threshold","Above margin threshold")))) -> Within margin threshold | L5: =IF(U5="","",IF(D5="Yes",IF(G5="","",IF((U5-G5)/G5>-0.02,"Too expensive",IF((U5-G5)/G5<-0.04,"Too cheap","Within range"))),IF(H5="","",IF(U5>H5,"Too expensive",IF(U5<H5*0.98,"Too cheap","Within range"))))) -> Too cheap | M5: =IF(OR(K5="",L5=""),"",IF(AND(K5="Within margin threshold",L5="Within range"),"No decision priority",IF(D5="Yes","Price positioning","Margin"))) -> Margin | N5: =IF(M5="No decision priority",U5, IF(D5="Yes", MROUND( IF(((G5*0.98)-F5)/(G5*0.98)<0.12, F5/(1-0.12), IF(((G5*0.98)-F5)/(G5*0.98)>0.16, F5/(1-0.16), G5*0.98)), 0.05), MROUND( IF(((H5*0.98)-F5)/(H5*0.98)<0.16, F5/(1-0.16), IF(((H5*0.98)-F5)/(H5*0.98)>0.2, F5/(1-0.2), H5*0.98)), 0.05))) -> 3.15 | O5: =IF(OR(N5="",U5=""),"",IF(N5<U5,"Decrease Price",IF(N5>U5,"Increase Price","Keep"))) -> Increase Price | P5: =IFERROR((N5-F5)/N5,"") -> 0.18095238 | Q5: =IF(N5="","",IF(D5="Yes",IF(G5="","",IF((N5-G5)/G5>-0.02,"Too expensive",IF((N5-G5)/G5<-0.04,"Too cheap","Within range"))),IF(H5="","",IF(N5>H5,"Too expensive",IF(N5<H5*0.98,"Too cheap","Within range"))))) -> Within range | R5: =IF(OR(N5="",P5=""),"",IF(D5="Yes",IF(P5<0.12,"Below margin threshold",IF(P5<=0.16,"Within margin threshold","Above margin threshold")),IF(P5<0.16,"Below margin threshold",IF(P5<=0.2,"Within margin threshold","Above margin threshold")))) -> Within margin threshold | S5: =IF(AND(R5="Within margin threshold",Q5="Within range"),"No conflict",IF(D5="Yes",IF(Q5<>"Within range","Price positioning conflict","Margin conflict"),IF(R5<>"Within margin threshold","Margin conflict","Price positioning conflict"))) -> No conflict | T5: =IF(S5="No conflict","Approve","Review") -> Approve | U5: =IF(E5<>"",E5,VLOOKUP(B5,'Pricing Engine V1'!$A:$G,7,FALSE)) -> 3.1 | V5: =IF(U5="","",IF(D5="Yes",(U5-G5)/G5,(U5-H5)/H5)) -> -0.03125 | W5: =IF(N5="","",IF(D5="Yes",(N5-G5)/G5,(N5-H5)/H5)) -> -0.015625 | X5: Medium | Y5: =IF(X5="High","High urgency",IF(X5="Medium","Balanced","Low urgency")) -> Balanced | Z5: =IF(Y5="High urgency","Immediate reaction required", IF(Y5="Low urgency","Monitor and adjust cautiously", "Standard pricing adjustment")) -> Standard pricing adjustment
A6: KVI item RSP when lowest competitor decreases price | B6: 1001 | C6: =VLOOKUP(B6,'Pricing Engine V1'!$A:$B,2,FALSE) -> Milk 1L | D6: =VLOOKUP(B6,'Pricing Engine V1'!$A:$V,22,FALSE) -> Yes | F6: =VLOOKUP(B6,'Pricing Engine V1'!$A:$H,8,FALSE) -> 2.15 | G6: 2.25 | H6: =VLOOKUP(B6,'Pricing Engine V1'!$A:$AB,28,FALSE) -> 2.4333333 | I6: =VLOOKUP(B6,'Pricing Engine V1'!$A:$AE,31,FALSE) -> 2.35 | J6: =IFERROR((U6-F6)/U6,"") -> 0.14 | K6: =IF(OR(U6="",F6=""),"",IF(D6="Yes",IF(J6<0.12,"Below margin threshold",IF(J6<=0.16,"Within margin threshold","Above margin threshold")),IF(J6<0.16,"Below margin threshold",IF(J6<=0.2,"Within margin threshold","Above margin threshold")))) -> Within margin threshold | L6: =IF(U6="","",IF(D6="Yes",IF(G6="","",IF((U6-G6)/G6>-0.02,"Too expensive",IF((U6-G6)/G6<-0.04,"Too cheap","Within range"))),IF(H6="","",IF(U6>H6,"Too expensive",IF(U6<H6*0.98,"Too cheap","Within range"))))) -> Too expensive | M6: =IF(OR(K6="",L6=""),"",IF(AND(K6="Within margin threshold",L6="Within range"),"No decision priority",IF(D6="Yes","Price positioning","Margin"))) -> Price positioning | N6: =IF(M6="No decision priority",U6, IF(D6="Yes", MROUND( IF(((G6*0.98)-F6)/(G6*0.98)<0.12, F6/(1-0.12), IF(((G6*0.98)-F6)/(G6*0.98)>0.16, F6/(1-0.16), G6*0.98)), 0.05), MROUND( IF(((H6*0.98)-F6)/(H6*0.98)<0.16, F6/(1-0.16), IF(((H6*0.98)-F6)/(H6*0.98)>0.2, F6/(1-0.2), H6*0.98)), 0.05))) -> 2.45 | O6: =IF(OR(N6="",U6=""),"",IF(N6<U6,"Decrease Price",IF(N6>U6,"Increase Price","Keep"))) -> Decrease Price | P6: =IFERROR((N6-F6)/N6,"") -> 0.12244898 | Q6: =IF(N6="","",IF(D6="Yes",IF(G6="","",IF((N6-G6)/G6>-0.02,"Too expensive",IF((N6-G6)/G6<-0.04,"Too cheap","Within range"))),IF(H6="","",IF(N6>H6,"Too expensive",IF(N6<H6*0.98,"Too cheap","Within range"))))) -> Too expensive | R6: =IF(OR(N6="",P6=""),"",IF(D6="Yes",IF(P6<0.12,"Below margin threshold",IF(P6<=0.16,"Within margin threshold","Above margin threshold")),IF(P6<0.16,"Below margin threshold",IF(P6<=0.2,"Within margin threshold","Above margin threshold")))) -> Within margin threshold | S6: =IF(AND(R6="Within margin threshold",Q6="Within range"),"No conflict",IF(D6="Yes",IF(Q6<>"Within range","Price positioning conflict","Margin conflict"),IF(R6<>"Within margin threshold","Margin conflict","Price positioning conflict"))) -> Price positioning conflict | T6: =IF(S6="No conflict","Approve","Review") -> Review | U6: =IF(E6<>"",E6,VLOOKUP(B6,'Pricing Engine V1'!$A:$G,7,FALSE)) -> 2.5 | V6: =IF(U6="","",IF(D6="Yes",(U6-G6)/G6,(U6-H6)/H6)) -> 0.11111111 | W6: =IF(N6="","",IF(D6="Yes",(N6-G6)/G6,(N6-H6)/H6)) -> 0.088888889 | X6: High | Y6: =IF(X6="High","High urgency",IF(X6="Medium","Balanced","Low urgency")) -> High urgency | Z6: =IF(Y6="High urgency","Immediate reaction required", IF(Y6="Low urgency","Monitor and adjust cautiously", "Standard pricing adjustment")) -> Immediate reaction required
